Workbook

Sheet Executive Summary
A1: KUSHWAHA TENT AJENCY
A2: Executive Business Performance, Sales, & Inventory Overview
A3: Location: Umesh Cinema Road, Hajipur - 844101, Bihar | Phone: 9431658931 | GSTIN: 10AYYPK5118M1Z1 | Period: Feb 2023 – Dec 2025
A5: 1. KEY FINANCIAL PERFORMANCE INDICATORS
A6: Metric Description | B6: Amount / Count | C6: Calculation / Source Sheet | D6: Notes
A7: Total Sales Invoiced | B7: ='Sales Invoices'!E183 -> 15303831 | C7: 'Sales Invoices'!E183 | D7: Total gross sales across 178 tax invoices
A8: Total Upfront Payments on Invoices | B8: ='Sales Invoices'!F183 -> 1025389 | C8: 'Sales Invoices'!F183 | D8: Immediate cash/bank received at time of invoice creation
A9: Total Outstanding on Invoices | B9: ='Sales Invoices'!G183 -> 14278442 | C9: 'Sales Invoices'!G183 | D9: Remaining unpaid balance on sales invoices
A10: Total Payments Received (Receipts) | B10: =SUMIF('Payments & Receipts'!D5:D215,"Payment In (Receipt)",'Payments & Receipts'!F5:F215) -> 9576476 | C10: 'Payments & Receipts' sheet | D10: Collections against past dues across 209 payment entries
A11: Total Outgoing Payments (Disbursements) | B11: =SUMIF('Payments & Receipts'!D5:D215,"Payment Out",'Payments & Receipts'!F5:F215) -> 250000 | C11: 'Payments & Receipts' sheet | D11: Disbursements to suppliers/vendors (Tent studio)
A12: Total Customer Outstanding Ledger Balances | B12: ='Parties Ledger'!H42 -> 4875466 | C12: 'Parties Ledger'!H42 | D12: Cumulative net receivables currently recorded in customer ledger
A13: Total Active Product Catalog SKUs | B13: =COUNTA('Item Master & Stock'!C5:C111) -> 107 | C13: 'Item Master & Stock'!C5:C111 | D13: Total number of unique items and materials in catalog
A14: Total Customers & Business Parties | B14: =COUNTA('Parties Ledger'!B5:B41) -> 37 | C14: 'Parties Ledger'!B5:B41 | D14: Total registered customer, vendor, and expense accounts
A17: 2. TOP 10 CUSTOMERS BY TOTAL SALES REVENUE
A18: Rank | B18: Customer / Party Name | C18: Contact Number | D18: Invoices Count | E18: Total Invoiced (₹) | F18: Current Balance (₹)
A19: 1 | B19: New kushwaha Tent Ajency Mahnar | C19: - | D19: 77 | E19: 8996661.8 | F19: 894263.76
A20: 2 | B20: Maharani electric and tent spare | C20: 80027 21806 | D20: 22 | E20: 2033948.3 | F20: 2033948.3
A21: 3 | B21: Hariyali Machinery and Electric | C21: 82929 25700 | D21: 23 | E21: 1133442.5 | F21: 33984.51
A22: 4 | B22: Pankaj tent house | C22: 8002721806 | D22: 18 | E22: 1092723 | F22: 1034409
A23: 5 | B23: Sohan Dj Sound | C23: 9304740919 | D23: 11 | E23: 543978.94 | F23: 8978.94
A24: 6 | B24: Rajiv tent house | C24: 8709715058 | D24: 2 | E24: 220400 | F24: 136400
A25: 7 | B25: Sonu kumar | C25: 8757293627 | D25: 1 | E25: 123000 | F25: 50000
A26: 8 | B26: J.P.K Enterprise | C26: 9431487455 | D26: 1 | E26: 120055 | F26: 0
A27: 9 | B27: Raja tent house | C27: 7488020540 | D27: 1 | E27: 113490 | F27: 63490
A28: 10 | B28: Abhishek and Arushi Enterprises | C28: 9097537676 | D28: 3 | E28: 101640 | F28: 21000
A30: 3. TOP 10 SELLING PRODUCTS & MATERIALS BY REVENUE
A31: Rank | B31: Item / Material Name | C31: Category | D31: Total Quantity Sold | E31: Unit | F31: Total Sales Revenue (₹)
A32: 1 | B32: clothes | C32: - | D32: 310973.75 | E32: Mtr | F32: 4985616
A33: 2 | B33: Plastic chair | C33: - | D33: 6973 | E33: Pcs | F33: 1756625
A34: 3 | B34: Avdesh clothes | C34: - | D34: 83980.25 | E34: Mtr | F34: 1413668.3
A35: 4 | B35: Print carpet | C35: - | D35: 145 | E35: Pcs | F35: 749650
A36: 5 | B36: Raj cooler 150ltr white copper | C36: - | D36: 20 | E36: Pcs | F36: 477600
A37: 6 | B37: Chadra table | C37: - | D37: 243 | E37: Pcs | F37: 399650
A38: 7 | B38: Bright clothes | C38: - | D38: 14924.25 | E38: F | F38: 317770.25
A39: 8 | B39: V.I.P chair | C39: - | D39: 346 | E39: Pcs | F39: 313940
A40: 9 | B40: Clothes mtr | C40: - | D40: 16591.5 | E40: Mtr | F40: 293020.44
A41: 10 | B41: Dari | C41: - | D41: 1930 | E41: Pcs | F41: 277110

Sheet Sales Invoices
A1: Kushwaha Tent Ajency — Sales Invoices Register
A2: Master register of all sales invoices issued between Feb 2023 and Dec 2025
A4: Sl No | B4: Invoice No | C4: Date | D4: Customer / Party Name | E4: Total Amount (₹) | F4: Paid Amount (₹) | G4: Balance Due (₹) | H4: Payment Status | I4: Payment Mode | J4: Description / Notes
A5: 1 | B5: 1 | C5: 2023-02-11 | D5: Rajiv tent house | E5: =F5+G5 -> 132400 | F5: 30000 | G5: 102400 | H5: =IF(G5<=0,"Paid",IF(F5>0,"Partial","Unpaid")) -> Partial | I5: Cash
A6: 2 | B6: 2 | C6: 2023-02-12 | D6: Raja tent house | E6: =F6+G6 -> 113490 | F6: 50000 | G6: 63490 | H6: =IF(G6<=0,"Paid",IF(F6>0,"Partial","Unpaid")) -> Partial | I6: Cash
A7: 3 | B7: 3 | C7: 2023-02-12 | D7: Pardeep kumar | E7: =F7+G7 -> 15709.5 | F7: 0 | G7: 15709.5 | H7: =IF(G7<=0,"Paid",IF(F7>0,"Partial","Unpaid")) -> Unpaid | I7: Cash
A8: 4 | B8: 4 | C8: 2023-02-12 | D8: R.D.S palace | E8: =F8+G8 -> 50000 | F8: 0 | G8: 50000 | H8: =IF(G8<=0,"Paid",IF(F8>0,"Partial","Unpaid")) -> Unpaid | I8: Cash
A9: 5 | B9: 5 | C9: 2023-02-14 | D9: gulshan tent house | E9: =F9+G9 -> 36000 | F9: 2000 | G9: 34000 | H9: =IF(G9<=0,"Paid",IF(F9>0,"Partial","Unpaid")) -> Partial | I9: Cash
A10: 6 | B10: 7 | C10: 2023-02-21 | D10: Pankaj tent house | E10: =F10+G10 -> 28647.5 | F10: 0 | G10: 28647.5 | H10: =IF(G10<=0,"Paid",IF(F10>0,"Partial","Unpaid")) -> Unpaid | I10: Cash
A11: 7 | B11: 8 | C11: 2023-03-07 | D11: Sonu kumar | E11: =F11+G11 -> 123000 | F11: 73000 | G11: 50000 | H11: =IF(G11<=0,"Paid",IF(F11>0,"Partial","Unpaid")) -> Partial | I11: Cash | J11: 5000- Account deposit 45000- cash
A12: 8 | B12: 9 | C12: 2023-04-05 | D12: Anil tent house | E12: =F12+G12 -> 45600 | F12: 24000 | G12: 21600 | H12: =IF(G12<=0,"Paid",IF(F12>0,"Partial","Unpaid")) -> Partial | I12: Cash
A13: 9 | B13: 10 | C13: 2023-04-09 | D13: shir ram tent house | E13: =F13+G13 -> 65500 | F13: 65500 | G13: 0 | H13: =IF(G13<=0,"Paid",IF(F13>0,"Partial","Unpaid")) -> Paid | I13: Cash
A14: 10 | B14: 11 | C14: 2023-04-11 | D14: Pankaj tent house | E14: =F14+G14 -> 191577.94 | F14: 58314 | G14: 133263.94 | H14: =IF(G14<=0,"Paid",IF(F14>0,"Partial","Unpaid")) -> Partial | I14: Cash
A15: 11 | B15: 12 | C15: 2023-04-14 | D15: Rajiv tent house | E15: =F15+G15 -> 88000 | F15: 34000 | G15: 54000 | H15: =IF(G15<=0,"Paid",IF(F15>0,"Partial","Unpaid")) -> Partial | I15: Cash
A16: 12 | B16: 13 | C16: 2023-04-14 | D16: Birju singh | E16: =F16+G16 -> 100000 | F16: 50000 | G16: 50000 | H16: =IF(G16<=0,"Paid",IF(F16>0,"Partial","Unpaid")) -> Partial | I16: Cash
A17: 13 | B17: 14 | C17: 2023-04-14 | D17: jitendra tent house | E17: =F17+G17 -> 100000 | F17: 90000 | G17: 10000 | H17: =IF(G17<=0,"Paid",IF(F17>0,"Partial","Unpaid")) -> Partial | I17: Cash
A18: 14 | B18: 16 | C18: 2023-04-19 | D18: Cafe D3 | E18: =F18+G18 -> 37000 | F18: 37000 | G18: 0 | H18: =IF(G18<=0,"Paid",IF(F18>0,"Partial","Unpaid")) -> Paid | I18: Cash
A19: 15 | B19: 17 | C19: 2023-04-21 | D19: Chauhan tent house | E19: =F19+G19 -> 84000 | F19: 84000 | G19: 0 | H19: =IF(G19<=0,"Paid",IF(F19>0,"Partial","Unpaid")) -> Paid | I19: Cash
A20: 16 | B20: 18 | C20: 2023-04-24 | D20: Pankaj tent house | E20: =F20+G20 -> 40945.63 | F20: 0 | G20: 40945.63 | H20: =IF(G20<=0,"Paid",IF(F20>0,"Partial","Unpaid")) -> Unpaid | I20: Cash
A21: 17 | B21: 19 | C21: 2023-04-28 | D21: Pankaj tent house | E21: =F21+G21 -> 23790.75 | F21: 0 | G21: 23790.75 | H21: =IF(G21<=0,"Paid",IF(F21>0,"Partial","Unpaid")) -> Unpaid | I21: Cash
A22: 18 | B22: 20 | C22: 2023-05-09 | D22: Pankaj tent house | E22: =F22+G22 -> 104877.5 | F22: 0 | G22: 104877.5 | H22: =IF(G22<=0,"Paid",IF(F22>0,"Partial","Unpaid")) -> Unpaid | I22: Cash
A23: 19 | B23: 21 | C23: 2023-05-12 | D23: Pankaj tent house | E23: =F23+G23 -> 87045 | F23: 0 | G23: 87045 | H23: =IF(G23<=0,"Paid",IF(F23>0,"Partial","Unpaid")) -> Unpaid | I23: Cash
... A83: 79 | B83: 80 | C83: 2024-05-12 | D83: Cafe D3 | E83: =F83+G83 -> 22500 | F83: 0 | G83: 22500 | H83: =IF(G83<=0,"Paid",IF(F83>0,"Partial","Unpaid")) -> Unpaid | I83: Cash
A84: 80 | B84: 81 | C84: 2024-05-12 | D84: New kushwaha Tent Ajency Mahnar | E84: =F84+G84 -> 125406.5 | F84: 33700 | G84: 91706.5 | H84: =IF(G84<=0,"Paid",IF(F84>0,"Partial","Unpaid")) -> Partial | I84: Cash | J84: table square - 10 p aaya hajipur green carpet- 1 p
A85: 81 | B85: 84 | C85: 2024-05-16 | D85: Sohan Dj Sound | E85: =F85+G85 -> 57000 | F85: 0 | G85: 57000 | H85: =IF(G85<=0,"Paid",IF(F85>0,"Partial","Unpaid")) -> Unpaid | I85: Cash
A86: 82 | B86: 101 | C86: 2024-05-22 | D86: Abhishek and Arushi Enterprises | E86: =F86+G86 -> 40320 | F86: 40320 | G86: 0 | H86: =IF(G86<=0,"Paid",IF(F86>0,"Partial","Unpaid")) -> Paid | I86: Kotak Mahindra Bank
A87: 83 | B87: 82 | C87: 2024-05-28 | D87: New kushwaha Tent Ajency Mahnar | E87: =F87+G87 -> 125000 | F87: 0 | G87: 125000 | H87: =IF(G87<=0,"Paid",IF(F87>0,"Partial","Unpaid")) -> Unpaid | I87: Cash
A88: 84 | B88: 83 | C88: 2024-06-05 | D88: Maharani electric and tent spare | E88: =F88+G88 -> 57349 | F88: 0 | G88: 57349 | H88: =IF(G88<=0,"Paid",IF(F88>0,"Partial","Unpaid")) -> Unpaid | I88: Cash
A89: 85 | B89: 85 | C89: 2024-06-05 | D89: Sohan Dj Sound | E89: =F89+G89 -> 29768 | F89: 0 | G89: 29768 | H89: =IF(G89<=0,"Paid",IF(F89>0,"Partial","Unpaid")) -> Unpaid | I89: Cash
A90: 86 | B90: 86 | C90: 2024-06-07 | D90: New kushwaha Tent Ajency Mahnar | E90: =F90+G90 -> 107453 | F90: 0 | G90: 107453 | H90: =IF(G90<=0,"Paid",IF(F90>0,"Partial","Unpaid")) -> Unpaid | I90: Cash
A91: 87 | B91: 100 | C91: 2024-06-18 | D91: Abhishek and Arushi Enterprises | E91: =F91+G91 -> 40320 | F91: 40320 | G91: 0 | H91: =IF(G91<=0,"Paid",IF(F91>0,"Partial","Unpaid")) -> Paid | I91: Kotak Mahindra Bank
A92: 88 | B92: 87 | C92: 2024-06-22 | D92: New kushwaha Tent Ajency Mahnar | E92: =F92+G92 -> 3900 | F92: 0 | G92: 3900 | H92: =IF(G92<=0,"Paid",IF(F92>0,"Partial","Unpaid")) -> Unpaid | I92: Cash
A93: 89 | B93: 88 | C93: 2024-06-23 | D93: Maharani electric and tent spare | E93: =F93+G93 -> 85165.13 | F93: 0 | G93: 85165.13 | H93: =IF(G93<=0,"Paid",IF(F93>0,"Partial","Unpaid")) -> Unpaid | I93: Cash
A94: 90 | B94: 89 | C94: 2024-06-23 | D94: Sohan Dj Sound | E94: =F94+G94 -> 5776 | F94: 0 | G94: 5776 | H94: =IF(G94<=0,"Paid",IF(F94>0,"Partial","Unpaid")) -> Unpaid | I94: Cash
A95: 91 | B95: 90 | C95: 2024-06-24 | D95: New kushwaha Tent Ajency Mahnar | E95: =F95+G95 -> 54551 | F95: 0 | G95: 54551 | H95: =IF(G95<=0,"Paid",IF(F95>0,"Partial","Unpaid")) -> Unpaid | I95: Cash
A96: 92 | B96: 91 | C96: 2024-07-05 | D96: Hariyali Machinery and Electric | E96: =F96+G96 -> 56196 | F96: 30000 | G96: 26196 | H96: =IF(G96<=0,"Paid",IF(F96>0,"Partial","Unpaid")) -> Partial | I96: Kotak Mahindra Bank
... A165: 161 | B165: 163 | C165: 2025-10-04 | D165: New kushwaha Tent Ajency Mahnar | E165: =F165+G165 -> 99088 | F165: 0 | G165: 99088 | H165: =IF(G165<=0,"Paid",IF(F165>0,"Partial","Unpaid")) -> Unpaid | I165: Kotak Mahindra Bank
A166: 162 | B166: 165 | C166: 2025-10-17 | D166: New kushwaha Tent Ajency Mahnar | E166: =F166+G166 -> 25500 | F166: 0 | G166: 25500 | H166: =IF(G166<=0,"Paid",IF(F166>0,"Partial","Unpaid")) -> Unpaid | I166: Kotak Mahindra Bank | J166: lm niwar
A167: 163 | B167: 164 | C167: 2025-10-25 | D167: New kushwaha Tent Ajency Mahnar | E167: =F167+G167 -> 48800 | F167: 0 | G167: 48800 | H167: =IF(G167<=0,"Paid",IF(F167>0,"Partial","Unpaid")) -> Unpaid | I167: Kotak Mahindra Bank
A168: 164 | B168: 166 | C168: 2025-11-01 | D168: New kushwaha Tent Ajency Mahnar | E168: =F168+G168 -> 17158 | F168: 0 | G168: 17158 | H168: =IF(G168<=0,"Paid",IF(F168>0,"Partial","Unpaid")) -> Unpaid | I168: Kotak Mahindra Bank
...

Sheet Invoice Line Items
A1: Kushwaha Tent Ajency — Detailed Invoice Line Items
A2: Itemized breakdown of products and services per sales invoice
A4: Sl No | B4: Invoice No | C4: Date | D4: Customer Name | E4: Item Name | F4: Category | G4: Quantity | H4: Unit | I4: Unit Price (₹) | J4: Discount (₹) | K4: Tax (₹) | L4: Line Total (₹)
A5: 1 | B5: 1 | C5: 2023-02-11 | D5: Rajiv tent house | E5: V.I.P chair | F5: - | G5: 100 | H5: Pcs | I5: 1200 | J5: 0 | K5: 0 | L5: =G5*I5-J5+K5 -> 120000
A6: 2 | B6: 1 | C6: 2023-02-11 | D6: Rajiv tent house | E6: Sundaram carpet | F6: - | G6: 2 | H6: Pcs | I6: 6200 | J6: 0 | K6: 0 | L6: =G6*I6-J6+K6 -> 12400
A7: 3 | B7: 2 | C7: 2023-02-12 | D7: Raja tent house | E7: Plain clothes | F7: - | G7: 1190 | H7: Mtr | I7: 18 | J7: 0 | K7: 0 | L7: =G7*I7-J7+K7 -> 21420
A8: 4 | B8: 2 | C8: 2023-02-12 | D8: Raja tent house | E8: Dari | F8: - | G8: 20 | H8: Pcs | I8: 200 | J8: 0 | K8: 0 | L8: =G8*I8-J8+K8 -> 4000
A9: 5 | B9: 2 | C9: 2023-02-12 | D9: Raja tent house | E9: Net clothes | F9: - | G9: 260 | H9: F | I9: 12 | J9: 0 | K9: 0 | L9: =G9*I9-J9+K9 -> 3120
A10: 6 | B10: 2 | C10: 2023-02-12 | D10: Raja tent house | E10: Raj coller 150ltr CPG | F10: - | G10: 2 | H10: Pcs | I10: 18500 | J10: 0 | K10: 0 | L10: =G10*I10-J10+K10 -> 37000
A11: 7 | B11: 2 | C11: 2023-02-12 | D11: Raja tent house | E11: Plastic chair | F11: - | G11: 150 | H11: Pcs | I11: 295 | J11: 0 | K11: 0 | L11: =G11*I11-J11+K11 -> 44250
A12: 8 | B12: 2 | C12: 2023-02-12 | D12: Raja tent house | E12: Phle ka baki paisa | F12: - | G12: 1 | I12: 3700 | J12: 0 | K12: 0 | L12: =G12*I12-J12+K12 -> 3700
A13: 9 | B13: 3 | C13: 2023-02-12 | D13: Pardeep kumar | E13: Plain clothes | F13: - | G13: 872.75 | H13: Mtr | I13: 18 | J13: 0 | K13: 0 | L13: =G13*I13-J13+K13 -> 15709.5
A14: 10 | B14: 4 | C14: 2023-02-12 | D14: R.D.S palace | E14: Raj cooler 150ltr white copper | F14: - | G14: 2 | H14: Pcs | I14: 25000 | J14: 0 | K14: 0 | L14: =G14*I14-J14+K14 -> 50000
A15: 11 | B15: 5 | C15: 2023-02-14 | D15: gulshan tent house | E15: Raj coller 150ltr CPG | F15: - | G15: 2 | H15: Pcs | I15: 18500 | J15: 1000 | K15: 0 | L15: =G15*I15-J15+K15 -> 36000
A16: 12 | B16: 7 | C16: 2023-02-21 | D16: Pankaj tent house | E16: Avdesh clothes | F16: - | G16: 1197 | H16: Mtr | I16: 17.5 | J16: 0 | K16: 0 | L16: =G16*I16-J16+K16 -> 20947.5
A17: 13 | B17: 7 | C17: 2023-02-21 | D17: Pankaj tent house | E17: Sidhi chota | F17: - | G17: 4 | H17: Pcs | I17: 1125 | J17: 0 | K17: 0 | L17: =G17*I17-J17+K17 -> 4500
A18: 14 | B18: 7 | C18: 2023-02-21 | D18: Pankaj tent house | E18: Sidhi 10ft | F18: - | G18: 2 | I18: 1600 | J18: 0 | K18: 0 | L18: =G18*I18-J18+K18 -> 3200
A19: 15 | B19: 8 | C19: 2023-03-07 | D19: Sonu kumar | E19: Raj cooler 150ltr white copper | F19: - | G19: 4 | H19: Pcs | I19: 24000 | J19: 2000 | K19: 0 | L19: =G19*I19-J19+K19 -> 94000
A20: 16 | B20: 8 | C20: 2023-03-07 | D20: Sonu kumar | E20: Plastic chair | F20: - | G20: 100 | H20: Pcs | I20: 290 | J20: 0 | K20: 0 | L20: =G20*I20-J20+K20 -> 29000
A21: 17 | B21: 9 | C21: 2023-04-05 | D21: Anil tent house | E21: Raj cooler 150ltr white copper | F21: - | G21: 2 | H21: Pcs | I21: 22800 | J21: 0 | K21: 0 | L21: =G21*I21-J21+K21 -> 45600
A22: 18 | B22: 10 | C22: 2023-04-09 | D22: shir ram tent house | E22: Raj coller 150 APG | F22: - | G22: 4 | H22: Pcs | I22: 16400 | J22: 100 | K22: 0 | L22: =G22*I22-J22+K22 -> 65500
A23: 19 | B23: 11 | C23: 2023-04-11 | D23: Pankaj tent house | E23: Avdesh clothes | F23: - | G23: 10708.75 | H23: Mtr | I23: 17.25 | J23: 0 | K23: 0 | L23: =G23*I23-J23+K23 -> 184725.94
A24: 20 | B24: 11 | C24: 2023-04-11 | D24: Pankaj tent house | E24: Bright clothes | F24: - | G24: 285.5 | H24: F | I24: 24 | J24: 0 | K24: 0 | L24: =G24*I24-J24+K24 -> 6852
A25: 21 | B25: 12 | C25: 2023-04-14 | D25: Rajiv tent house | E25: Raj cooler 150ltr white copper | F25: - | G25: 4 | H25: Pcs | I25: 22000 | J25: 0 | K25: 0 | L25: =G25*I25-J25+K25 -> 88000
A26: 22 | B26: 13 | C26: 2023-04-14 | D26: Birju singh | E26: Raj cooler 150ltr white copper | F26: - | G26: 4 | H26: Pcs | I26: 25000 | J26: 0 | K26: 0 | L26: =G26*I26-J26+K26 -> 100000
A27: 23 | B27: 14 | C27: 2023-04-14 | D27: jitendra tent house | E27: Raj cooler 150ltr white copper | F27: - | G27: 4 | H27: Pcs | I27: 25000 | J27: 0 | K27: 0 | L27: =G27*I27-J27+K27 -> 100000
A28: 24 | B28: 16 | C28: 2023-04-19 | D28: Cafe D3 | E28: Raj coller 150ltr CPG | F28: - | G28: 2 | H28: Pcs | I28: 18500 | J28: 0 | K28: 0 | L28: =G28*I28-J28+K28 -> 37000
A29: 25 | B29: 17 | C29: 2023-04-21 | D29: Chauhan tent house | E29: Raj cooler 150ltr white copper 3 blade | F29: - | G29: 4 | H29: Pcs | I29: 21000 | J29: 0 | K29: 0 | L29: =G29*I29-J29+K29 -> 84000
A30: 26 | B30: 18 | C30: 2023-04-24 | D30: Pankaj tent house | E30: Avdesh clothes | F30: - | G30: 2339.75 | H30: Mtr | I30: 17.5 | J30: 0 | K30: 0 | L30: =G30*I30-J30+K30 -> 40945.625
... A47: 43 | B47: 30 | C47: 2023-08-16 | D47: Pankaj tent house | E47: Avdesh clothes | F47: - | G47: 1841 | H47: Mtr | I47: 16.5 | J47: 0 | K47: 0 | L47: =G47*I47-J47+K47 -> 30376.5
A48: 44 | B48: 30 | C48: 2023-08-16 | D48: Pankaj tent house | E48: Phle ka baki paisa | F48: - | G48: 1 | I48: 1000 | J48: 0 | K48: 0 | L48: =G48*I48-J48+K48 -> 1000
A49: 45 | B49: 31 | C49: 2023-10-03 | D49: Maharani electric and tent spare | E49: Avdesh clothes | F49: - | G49: 13374.25 | H49: Mtr | I49: 16 | J49: 0 | K49: 0 | L49: =G49*I49-J49+K49 -> 213988
A50: 46 | B50: 32 | C50: 2023-10-05 | D50: Maharani electric and tent spare | E50: Avdesh clothes | F50: - | G50: 4595.25 | H50: Mtr | I50: 16 | J50: 0 | K50: 0 | L50: =G50*I50-J50+K50 -> 73524
A51: 47 | B51: 33 | C51: 2023-11-24 | D51: Pankaj tent house | E51: clothes | F51: - | G51: 5912 | H51: Mtr | I51: 16.25 | J51: 0 | K51: 0 | L51: =G51*I51-J51+K51 -> 96070
A52: 48 | B52: 33 | C52: 2023-11-24 | D52: Pankaj tent house | E52: Sidhi chota | F52: - | G52: 4 | H52: Pcs | I52: 1125 | J52: 0 | K52: 0 | L52: =G52*I52-J52+K52 -> 4500
A53: 49 | B53: 33 | C53: 2023-11-24 | D53: Pankaj tent house | E53: Sidhi 10ft | F53: - | G53: 1 | I53: 1700 | J53: 0 | K53: 0 | L53: =G53*I53-J53+K53 -> 1700
A54: 50 | B54: 33 | C54: 2023-11-24 | D54: Pankaj tent house | E54: Patiya | F54: - | G54: 499 | H54: Mtr | I54: 12.5 | J54: 0 | K54: 0 | L54: =G54*I54-J54+K54 -> 6237.5
A55: 51 | B55: 34 | C55: 2023-12-05 | D55: Pankaj tent house | E55: Safeda | F55: - | G55: 185.7 | H55: Mtr | I55: 55 | J55: 0 | K55: 0 | L55: =G55*I55-J55+K55 -> 10213.5
A56: 52 | B56: 34 | C56: 2023-12-05 | D56: Pankaj tent house | E56: clothes | F56: - | G56: 4980.75 | H56: Mtr | I56: 16.25 | J56: 0 | K56: 0 | L56: =G56*I56-J56+K56 -> 80937.188
A57: 53 | B57: 36 | C57: 2023-12-12 | D57: Pankaj tent house | E57: clothes | F57: - | G57: 1588.5 | H57: Mtr | I57: 16 | J57: 0 | K57: 0 | L57: =G57*I57-J57+K57 -> 25416
...

Sheet Payments & Receipts
A1: Kushwaha Tent Ajency — Payments & Receipts Register
A2: Money receipts from customers (Payment-In) and vendor/expense disbursements (Payment-Out)
A4: Sl No | B4: Receipt / Ref No | C4: Date | D4: Voucher Type | E4: Party Name | F4: Amount (₹) | G4: Payment Mode | H4: Notes / Reference
A5: 1 | B5: 1 | C5: 2023-02-11 | D5: Payment In (Receipt) | E5: Rajiv tent house | F5: 20000 | G5: Cash
A6: 2 | B6: 2 | C6: 2023-04-16 | D6: Payment In (Receipt) | E6: Guddu shaa | F6: 25000 | G6: Cash
A7: 3 | B7: REC-37 | C7: 2023-10-28 | D7: Payment Out | E7: Tent studio | F7: 100000 | G7: Cash
A8: 4 | B8: REC-36 | C8: 2023-11-10 | D8: Payment Out | E8: Tent studio | F8: 150000 | G8: Cash
A9: 5 | B9: 3 | C9: 2024-02-12 | D9: Payment In (Receipt) | E9: New kushwaha Tent Ajency Mahnar | F9: 45000 | G9: Cash
A10: 6 | B10: 4 | C10: 2024-02-17 | D10: Payment In (Receipt) | E10: New kushwaha Tent Ajency Mahnar | F10: 40000 | G10: Cash
A11: 7 | B11: 5 | C11: 2024-02-17 | D11: Payment In (Receipt) | E11: New kushwaha Tent Ajency Mahnar | F11: 31000 | G11: Cheque
A12: 8 | B12: 6 | C12: 2024-02-20 | D12: Payment In (Receipt) | E12: New kushwaha Tent Ajency Mahnar | F12: 26000 | G12: Cash | H12: 600 rajkumar thela 400 thela cash -25000 received hua
A13: 9 | B13: 7 | C13: 2024-02-22 | D13: Payment In (Receipt) | E13: New kushwaha Tent Ajency Mahnar | F13: 80000 | G13: Cash
A14: 10 | B14: 8 | C14: 2024-02-23 | D14: Payment In (Receipt) | E14: New kushwaha Tent Ajency Mahnar | F14: 10000 | G14: Cheque
A15: 11 | B15: 9 | C15: 2024-02-28 | D15: Payment In (Receipt) | E15: New kushwaha Tent Ajency Mahnar | F15: 65000 | G15: Cash
A16: 12 | B16: 18 | C16: 2024-02-28 | D16: Payment In (Receipt) | E16: D green | F16: 25000 | G16: Kotak Mahindra Bank
A17: 13 | B17: 10 | C17: 2024-03-01 | D17: Payment In (Receipt) | E17: New kushwaha Tent Ajency Mahnar | F17: 15500 | G17: Cash
A18: 14 | B18: 11 | C18: 2024-03-04 | D18: Payment In (Receipt) | E18: New kushwaha Tent Ajency Mahnar | F18: 40000 | G18: Cash
A19: 15 | B19: 13 | C19: 2024-03-05 | D19: Payment In (Receipt) | E19: New kushwaha Tent Ajency Mahnar | F19: 17000 | G19: Cash
A20: 16 | B20: 12 | C20: 2024-03-06 | D20: Payment In (Receipt) | E20: New kushwaha Tent Ajency Mahnar | F20: 45000 | G20: Cash
A21: 17 | B21: 14 | C21: 2024-03-14 | D21: Payment In (Receipt) | E21: New kushwaha Tent Ajency Mahnar | F21: 245000 | G21: Cash
A22: 18 | B22: 15 | C22: 2024-03-15 | D22: Payment In (Receipt) | E22: New kushwaha Tent Ajency Mahnar | F22: 14000 | G22: Cash
A23: 19 | B23: 16 | C23: 2024-03-16 | D23: Payment In (Receipt) | E23: New kushwaha Tent Ajency Mahnar | F23: 30000 | G23: Kotak Mahindra Bank
A24: 20 | B24: 17 | C24: 2024-03-18 | D24: Payment In (Receipt) | E24: New kushwaha Tent Ajency Mahnar | F24: 70000 | G24: Cash
... A28: 24 | B28: 22 | C28: 2024-04-05 | D28: Payment In (Receipt) | E28: New kushwaha Tent Ajency Mahnar | F28: 50000 | G28: Kotak Mahindra Bank
A29: 25 | B29: 23 | C29: 2024-04-06 | D29: Payment In (Receipt) | E29: New kushwaha Tent Ajency Mahnar | F29: 86000 | G29: Cash | H29: chair 100p
A30: 26 | B30: 24 | C30: 2024-04-07 | D30: Payment In (Receipt) | E30: New kushwaha Tent Ajency Mahnar | F30: 62000 | G30: Cash
A31: 27 | B31: 25 | C31: 2024-04-07 | D31: Payment In (Receipt) | E31: New kushwaha Tent Ajency Mahnar | F31: 57000 | G31: Cash
A32: 28 | B32: 26 | C32: 2024-04-11 | D32: Payment In (Receipt) | E32: Sohan Dj Sound | F32: 10000 | G32: Cash
A33: 29 | B33: 27 | C33: 2024-04-12 | D33: Payment In (Receipt) | E33: New kushwaha Tent Ajency Mahnar | F33: 50000 | G33: Kotak Mahindra Bank
A34: 30 | B34: 28 | C34: 2024-04-12 | D34: Payment In (Receipt) | E34: New kushwaha Tent Ajency Mahnar | F34: 135000 | G34: Cash
A35: 31 | B35: 29 | C35: 2024-04-15 | D35: Payment In (Receipt) | E35: Sohan Dj Sound | F35: 20000 | G35: Cash
A36: 32 | B36: 30 | C36: 2024-04-17 | D36: Payment In (Receipt) | E36: New kushwaha Tent Ajency Mahnar | F36: 150000 | G36: Cash
A37: 33 | B37: 31 | C37: 2024-04-18 | D37: Payment In (Receipt) | E37: New kushwaha Tent Ajency Mahnar | F37: 20000 | G37: Kotak Mahindra Bank
A38: 34 | B38: 32 | C38: 2024-04-18 | D38: Payment In (Receipt) | E38: New kushwaha Tent Ajency Mahnar | F38: 3000 | G38: Cash
A39: 35 | B39: 33 | C39: 2024-04-20 | D39: Payment In (Receipt) | E39: Sohan Dj Sound | F39: 30000 | G39: Cash
A40: 36 | B40: 34 | C40: 2024-04-20 | D40: Payment In (Receipt) | E40: New shrivastav Tent Ajency | F40: 5000 | G40: Cash
A41: 37 | B41: 35 | C41: 2024-04-21 | D41: Payment In (Receipt) | E41: New kushwaha Tent Ajency Mahnar | F41: 80000 | G41: Kotak Mahindra Bank
... A53: 49 | B53: 47 | C53: 2024-05-02 | D53: Payment In (Receipt) | E53: New kushwaha Tent Ajency Mahnar | F53: 40000 | G53: Kotak Mahindra Bank
A54: 50 | B54: 48 | C54: 2024-05-02 | D54: Payment In (Receipt) | E54: New kushwaha Tent Ajency Mahnar | F54: 10000 | G54: Cash | H54: gadi bhada or tampu bada or parda solve total bada
A55: 51 | B55: 49 | C55: 2024-05-03 | D55: Payment In (Receipt) | E55: Sohan Dj Sound | F55: 20000 | G55: Cash
...

Sheet Parties Ledger
A1: Kushwaha Tent Ajency — Parties & Customer Accounts
A2: Customer, supplier, and expense account balances, contact details, and transaction history
A4: Sl No | B4: Party Name | C4: Party Type | D4: Phone Number | E4: Address / City | F4: State | G4: GSTIN | H4: Current Balance (₹) | I4: Invoices Count | J4: Total Invoiced (₹)
A5: 1 | B5: New kushwaha Tent Ajency Mahnar | C5: Customer | D5: - | E5: - | F5: Bihar | G5: - | H5: 894263.76 | I5: 77 | J5: 8996661.8
A6: 2 | B6: Maharani electric and tent spare | C6: Customer | D6: 80027 21806 | E6: BHAGWANPUR N/A WARD NO-13 Bhagwanpur | F6: Bihar | G6: 10BSJPK0507N1ZY | H6: 2033948.3 | I6: 22 | J6: 2033948.3
A7: 3 | B7: Hariyali Machinery and Electric | C7: Customer | D7: 82929 25700 | E7: - | F7: Bihar | G7: - | H7: 33984.51 | I7: 23 | J7: 1133442.5
A8: 4 | B8: Pankaj tent house | C8: Customer | D8: 8002721806 | E8: - | F8: Bihar | G8: - | H8: 1034409 | I8: 18 | J8: 1092723
A9: 5 | B9: Sohan Dj Sound | C9: Customer | D9: 9304740919 | E9: - | F9: Bihar | G9: - | H9: 8978.94 | I9: 11 | J9: 543978.94
A10: 6 | B10: Rajiv tent house | C10: Customer | D10: 8709715058 | E10: - | F10: Bihar | G10: - | H10: 136400 | I10: 2 | J10: 220400
A11: 7 | B11: Sonu kumar | C11: Customer | D11: 8757293627 | E11: - | F11: Bihar | G11: - | H11: 50000 | I11: 1 | J11: 123000
A12: 8 | B12: J.P.K Enterprise | C12: Customer | D12: 9431487455 | E12: JPK ENTERPRISES 01 Rasulpur fatah, Mahua Rasulpur Fateh | F12: Bihar | G12: 10ARYPK2680H1ZL | H12: 0 | I12: 1 | J12: 120055
A13: 9 | B13: Raja tent house | C13: Customer | D13: 7488020540 | E13: - | F13: Bihar | G13: - | H13: 63490 | I13: 1 | J13: 113490
A14: 10 | B14: Abhishek and Arushi Enterprises | C14: Customer | D14: 9097537676 | E14: GROUND NAWADA KALA WARD NO 45 NAWADA KALA WARD NO 45 NAWADA KALA WARD NO 45 Hajipur | F14: Bihar | G14: 10GDUPK8458K1ZT | H14: 21000 | I14: 3 | J14: 101640
A15: 11 | B15: Birju singh | C15: Customer | D15: 9798456561 | E15: - | F15: Bihar | G15: - | H15: 50000 | I15: 1 | J15: 100000
A16: 12 | B16: jitendra tent house | C16: Customer | D16: 9507894145 | E16: - | F16: Bihar | G16: - | H16: 10000 | I16: 1 | J16: 100000
... A41: 37 | B41: Guddu shaa | C41: Customer | D41: 9931083840 | E41: - | F41: Bihar | G41: - | H41: -25000 | I41: 0 | J41: 0
G42: Total | H42: =SUM(H5:H41) -> 4875466 | I42: =SUM(I5:I41) -> 178 | J42: =SUM(J5:J41) -> 15303831

Sheet Item Master & Stock
A1: Kushwaha Tent Ajency — Product Catalog & Stock Inventory
A2: Inventory of tent materials, cloth, chairs, electricals, coolers, and spare parts
A4: Sl No | B4: Item Code | C4: Item Name | D4: Category | E4: Unit | F4: Sale Price (₹) | G4: Purchase Price (₹) | H4: Stock Quantity | I4: Stock Value (₹) | J4: Status
A5: 1 | B5: ITM-048 | C5: 3 tala jhumar | D5: - | E5: Pcs | F5: 300 | G5: 0 | H5: -10 | I5: 0 | J5: Active
A6: 2 | B6: ITM-044 | C6: 5fit red and yellow cloth | D6: - | E6: Mtr | F6: 45 | G6: 0 | H6: -148 | I6: 0 | J6: Active
A7: 3 | B7: ITM-075 | C7: Aluminium Motor | D7: - | E7: Pcs | F7: 3500 | G7: 3500 | H7: -7 | I7: 0 | J7: Active
A8: 4 | B8: ITM-015 | C8: Avdesh clothes | D8: - | E8: Mtr | F8: 17.5 | G8: 0 | H8: -83980.25 | I8: 0 | J8: Active
A9: 5 | B9: ITM-002 | C9: Bright clothes | D9: - | E9: F | F9: 24 | G9: 0 | H9: -14924.25 | I9: 0 | J9: Active
A10: 6 | B10: ITM-029 | C10: Chadra table | D10: - | E10: Pcs | F10: 1700 | G10: 0 | H10: -243 | I10: 0 | J10: Active
A11: 7 | B11: ITM-003 | C11: Chair cover | D11: - | E11: Pcs | F11: 55 | G11: 0 | H11: -250 | I11: 0 | J11: Active
A12: 8 | B12: ITM-089 | C12: Chinese jhalar | D12: - | E12: Pcs | F12: 42 | G12: 0 | H12: -725 | I12: 0 | J12: Active
A13: 9 | B13: ITM-055 | C13: Clothes mtr | D13: - | E13: Mtr | F13: 236 | G13: 0 | H13: -16591.5 | I13: 0 | J13: Active
A14: 10 | B14: ITM-099 | C14: Clothes mtr (pila) | D14: - | E14: Mtr | F14: 17.25 | G14: 0 | H14: -4074 | I14: 0 | J14: Active
A15: 11 | B15: ITM-104 | C15: Coffee machine | D15: - | E15: Pcs | F15: 11400 | G15: 0 | H15: -1 | I15: 0 | J15: Active
A16: 12 | B16: ITM-074 | C16: Copper Motor | D16: - | E16: Pcs | F16: 4500 | G16: 4500 | H16: -10 | I16: 0 | J16: Active
... A28: 24 | B28: ITM-083 | C28: Hitlon cover | D28: - | E28: Pcs | F28: 120 | G28: 0 | H28: -115 | I28: 0 | J28: Active
A29: 25 | B29: ITM-105 | C29: Hitlon cover saath | D29: - | F29: 18 | G29: 0 | H29: -390 | I29: 0 | J29: Active
A30: 26 | B30: ITM-006 | C30: Jhalar | D30: - | E30: Pcs | F30: 400 | G30: 0 | H30: -530 | I30: 0 | J30: Active
A31: 27 | B31: ITM-076 | C31: Jhalar 1ft | D31: - | E31: Pcs | F31: 8 | G31: 0 | H31: -396 | I31: 0 | J31: Active
A32: 28 | B32: ITM-095 | C32: Jhumar Crystal (B) | D32: - | E32: Pcs | F32: 2000 | G32: 0 | H32: -2 | I32: 0 | J32: Active
A33: 29 | B33: ITM-046 | C33: Jhumar charkor | D33: - | E33: Pcs | F33: 325 | G33: 0 | H33: -17 | I33: 0 | J33: Active
A34: 30 | B34: ITM-094 | C34: Jhumar crystal (M) | D34: - | E34: Pcs | F34: 1550 | G34: 0 | H34: -2 | I34: 0 | J34: Active
A35: 31 | B35: ITM-045 | C35: Jhumar ghanti | D35: - | E35: Pcs | F35: 180 | G35: 0 | H35: -10 | I35: 0 | J35: Active
A36: 32 | B36: ITM-069 | C36: Jhumar plastic | D36: - | E36: Pcs | F36: 200 | G36: 0 | H36: -35 | I36: 0 | J36: Active
A37: 33 | B37: ITM-071 | C37: Kalin | D37: - | E37: Pcs | F37: 1200 | G37: 0 | H37: -8 | I37: 0 | J37: Active
A38: 34 | B38: ITM-079 | C38: Kambal | D38: - | E38: Pcs | F38: 440 | G38: 0 | H38: -508 | I38: 0 | J38: Active
A39: 35 | B39: ITM-016 | C39: Khatu shree clothes | D39: - | E39: Mtr | F39: 16.5 | G39: 0 | H39: 0 | I39: 0 | J39: Active
A40: 36 | B40: ITM-059 | C40: Lais | D40: - | E40: Pcs | F40: 55 | G40: 0 | H40: -6 | I40: 0 | J40: Active
A41: 37 | B41: ITM-082 | C41: Lala lali | D41: - | E41: Pcs | F41: 1600 | G41: 0 | H41: -4 | I41: 0 | J41: Active
... A47: 43 | B47: ITM-037 | C47: Maharaja | D47: - | E47: Pcs | F47: 8500 | G47: 0 | H47: -18 | I47: 0 | J47: Active
A48: 44 | B48: ITM-049 | C48: Nagin jhumar | D48: - | F48: 275 | G48: 0 | H48: -10 | I48: 0 | J48: Active
A49: 45 | B49: ITM-005 | C49: Net clothes | D49: - | E49: F | F49: 12 | G49: 0 | H49: -10361.25 | I49: 0 | J49: Active
A50: 46 | B50: ITM-077 | C50: Net jhalar | D50: - | E50: Pcs | F50: 150 | G50: 0 | H50: -20 | I50: 0 | J50: Active
A51: 47 | B51: ITM-050 | C51: Niwar | D51: - | E51: Pcs | F51: 0 | G51: 0 | H51: -11 | I51: 0 | J51: Active
A52: 48 | B52: ITM-051 | C52: On selling | D52: - | E52: Pcs | F52: 850 | G52: 0 | H52: -14 | I52: 0 | J52: Active
A53: 49 | B53: ITM-052 | C53: On selling 10*15 | D53: - | F53: 900 | G53: 0 | H53: -24 | I53: 0 | J53: Active
A54: 50 | B54: ITM-053 | C54: On selling 15*15 | D54: - | E54: Pcs | F54: 1100 | G54: 0 | H54: -3 | I54: 0 | J54: Active
A55: 51 | B55: ITM-096 | C55: Par light | D55: - | E55: Pcs | F55: 550 | G55: 0 | H55: -80 | I55: 0 | J55: Active
A56: 52 | B56: ITM-073 | C56: Parda | D56: - | E56: Pcs | F56: 575 | G56: 0 | H56: -254 | I56: 0 | J56: Active
A57: 53 | B57: ITM-026 | C57: Parda kamdar | D57: - | E57: Pcs | F57: 800 | G57: 0 | H57: -128 | I57: 0 | J57: Active
...

Sheet All Transactions Register
A1: Kushwaha Tent Ajency — Complete Transactions Register
A2: Chronological audit of all 391 business transactions (Sales, Receipts, Payments, Returns)
A4: Sl No | B4: Txn ID | C4: Date | D4: Voucher Type | E4: Ref / Inv No | F4: Party Name | G4: Inflow / Credit (₹) | H4: Outflow / Debit (₹) | I4: Balance Amount (₹) | J4: Payment Mode | K4: Description / Remarks
A5: 1 | B5: 1 | C5: 2023-02-11 | D5: Sale | E5: 1 | F5: Rajiv tent house | G5: 30000 | H5: 0 | I5: 102400 | J5: Cash
A6: 2 | B6: 2 | C6: 2023-02-11 | D6: Payment In (Receipt) | E6: 1 | F6: Rajiv tent house | G6: 20000 | H6: 0 | I6: 0 | J6: Cash
A7: 3 | B7: 3 | C7: 2023-02-12 | D7: Sale | E7: 2 | F7: Raja tent house | G7: 50000 | H7: 0 | I7: 63490 | J7: Cash
A8: 4 | B8: 4 | C8: 2023-02-12 | D8: Sale | E8: 3 | F8: Pardeep kumar | G8: 0 | H8: 0 | I8: 15709.5 | J8: Cash
A9: 5 | B9: 5 | C9: 2023-02-12 | D9: Sale | E9: 4 | F9: R.D.S palace | G9: 0 | H9: 0 | I9: 50000 | J9: Cash
A10: 6 | B10: 6 | C10: 2023-02-14 | D10: Sale | E10: 5 | F10: gulshan tent house | G10: 2000 | H10: 0 | I10: 34000 | J10: Cash
A11: 7 | B11: 8 | C11: 2023-02-21 | D11: Sale | E11: 7 | F11: Pankaj tent house | G11: 0 | H11: 0 | I11: 28647.5 | J11: Cash
A12: 8 | B12: 9 | C12: 2023-03-07 | D12: Sale | E12: 8 | F12: Sonu kumar | G12: 73000 | H12: 0 | I12: 50000 | J12: Cash | K12: 5000- Account deposit 45000- cash
A13: 9 | B13: 10 | C13: 2023-04-05 | D13: Sale | E13: 9 | F13: Anil tent house | G13: 24000 | H13: 0 | I13: 21600 | J13: Cash
A14: 10 | B14: 11 | C14: 2023-04-09 | D14: Sale | E14: 10 | F14: shir ram tent house | G14: 65500 | H14: 0 | I14: 0 | J14: Cash
A15: 11 | B15: 12 | C15: 2023-04-11 | D15: Sale | E15: 11 | F15: Pankaj tent house | G15: 58314 | H15: 0 | I15: 133263.94 | J15: Cash
A16: 12 | B16: 13 | C16: 2023-04-14 | D16: Sale | E16: 12 | F16: Rajiv tent house | G16: 34000 | H16: 0 | I16: 54000 | J16: Cash
A17: 13 | B17: 14 | C17: 2023-04-14 | D17: Sale | E17: 13 | F17: Birju singh | G17: 50000 | H17: 0 | I17: 50000 | J17: Cash
A18: 14 | B18: 15 | C18: 2023-04-14 | D18: Sale | E18: 14 | F18: jitendra tent house | G18: 90000 | H18: 0 | I18: 10000 | J18: Cash
A19: 15 | B19: 17 | C19: 2023-04-16 | D19: Payment In (Receipt) | E19: 2 | F19: Guddu shaa | G19: 25000 | H19: 0 | I19: 0 | J19: Cash
A20: 16 | B20: 18 | C20: 2023-04-19 | D20: Sale | E20: 16 | F20: Cafe D3 | G20: 37000 | H20: 0 | I20: 0 | J20: Cash
A21: 17 | B21: 19 | C21: 2023-04-21 | D21: Sale | E21: 17 | F21: Chauhan tent house | G21: 84000 | H21: 0 | I21: 0 | J21: Cash
A22: 18 | B22: 20 | C22: 2023-04-24 | D22: Sale | E22: 18 | F22: Pankaj tent house | G22: 0 | H22: 0 | I22: 40945.63 | J22: Cash
A23: 19 | B23: 21 | C23: 2023-04-28 | D23: Sale | E23: 19 | F23: Pankaj tent house | G23: 0 | H23: 0 | I23: 23790.75 | J23: Cash
A24: 20 | B24: 22 | C24: 2023-05-09 | D24: Sale | E24: 20 | F24: Pankaj tent house | G24: 0 | H24: 0 | I24: 104877.5 | J24: Cash
... A55: 51 | B55: 53 | C55: 2024-02-20 | D55: Sale | E55: 45 | F55: New kushwaha Tent Ajency Mahnar | G55: 0 | H55: 0 | I55: 134075.28 | J55: Cash
A56: 52 | B56: 54 | C56: 2024-02-20 | D56: Payment In (Receipt) | E56: 6 | F56: New kushwaha Tent Ajency Mahnar | G56: 26000 | H56: 0 | I56: 0 | J56: Cash | K56: 600 rajkumar thela 400 thela cash -25000 received hua
A57: 53 | B57: 55 | C57: 2024-02-22 | D57: Payment In (Receipt) | E57: 7 | F57: New kushwaha Tent Ajency Mahnar | G57: 80000 | H57: 0 | I57: 0 | J57: Cash
A58: 54 | B58: 58 | C58: 2024-02-23 | D58: Payment In (Receipt) | E58: 8 | F58: New kushwaha Tent Ajency Mahnar | G58: 10000 | H58: 0 | I58: 0 | J58: Cheque
A59: 55 | B59: 56 | C59: 2024-02-25 | D59: Sale | E59: 46 | F59: D green | G59: 0 | H59: 0 | I59: 47000 | J59: Cash
A60: 56 | B60: 57 | C60: 2024-02-25 | D60: Sale | E60: 47 | F60: New kushwaha Tent Ajency Mahnar | G60: 0 | H60: 0 | I60: 176167.4 | J60: Cash
A61: 57 | B61: 59 | C61: 2024-02-26 | D61: Sale | E61: 48 | F61: Maharani electric and tent spare | G61: 0 | H61: 0 | I61: 73206.5 | J61: Cash
A62: 58 | B62: 60 | C62: 2024-02-28 | D62: Payment In (Receipt) | E62: 9 | F62: New kushwaha Tent Ajency Mahnar | G62: 65000 | H62: 0 | I62: 0 | J62: Cash
A63: 59 | B63: 61 | C63: 2024-02-28 | D63: Sale | E63: 49 | F63: New kushwaha Tent Ajency Mahnar | G63: 0 | H63: 0 | I63: 7150 | J63: Cash
A64: 60 | B64: 78 | C64: 2024-02-28 | D64: Payment In (Receipt) | E64: 18 | F64: D green | G64: 25000 | H64: 0 | I64: 0 | J64: Kotak Mahindra Bank
A65: 61 | B65: 62 | C65: 2024-03-01 | D65: Payment In (Receipt) | E65: 10 | F65: New kushwaha Tent Ajency Mahnar | G65: 15500 | H65: 0 | I65: 0 | J65: Cash
A66: 62 | B66: 63 | C66: 2024-03-02 | D66: Sale | E66: 50 | F66: New kushwaha Tent Ajency Mahnar | G66: 0 | H66: 0 | I66: 106490 | J66: Cash
A67: 63 | B67: 64 | C67: 2024-03-04 | D67: Payment In (Receipt) | E67: 11 | F67: New kushwaha Tent Ajency Mahnar | G67: 40000 | H67: 0 | I67: 0 | J67: Cash
A68: 64 | B68: 65 | C68: 2024-03-05 | D68: Sale | E68: 51 | F68: New kushwaha Tent Ajency Mahnar | G68: 0 | H68: 0 | I68: 288653 | J68: Cash
... A91: 87 | B91: 89 | C91: 2024-04-05 | D91: Sale | E91: 63 | F91: New kushwaha Tent Ajency Mahnar | G91: 0 | H91: 0 | I91: 57818.13 | J91: Cash
A92: 88 | B92: 90 | C92: 2024-04-06 | D92: Payment In (Receipt) | E92: 23 | F92: New kushwaha Tent Ajency Mahnar | G92: 86000 | H92: 0 | I92: 0 | J92: Cash | K92: chair 100p
A93: 89 | B93: 91 | C93: 2024-04-07 | D93: Payment In (Receipt) | E93: 24 | F93: New kushwaha Tent Ajency Mahnar | G93: 62000 | H93: 0 | I93: 0 | J93: Cash
...
